Workbook
Name Admin_Cost_per_day: #REF!
Name Admin.costperday: #REF!
Name Admin.costperroom: #REF!
Name Buffet_Breakfast_cost_per_room: #REF!
Name buffet.breakfas.costperroom: #REF!
Name Contribution_margin_per_unit: [1]Model!$C$4
Name Cost_of_parts_per_unit: [1]Model!$H$5
Name Daily_Miscellaneous_expense: #REF!
Name daily_miscellaneous_expense1: #REF!
Name daily_miscellaneous_expenses: #REF!
Name Daily_Online_Reservation: #REF!
Name daily_online_reservation1: #REF!
Name daily_online_reservations: #REF!
Name daily.miscellaneous.expense: #REF!
Name daily.online.reservation: #REF!
Name Demand: [1]Model!$H$6
Name Direct_labour_cost_per_unit: [1]Model!$H$4
Name First_year_profit: [1]Model!$C$6
Name House_Keeping_Cost_per_room: #REF!
Name Housekeeping.costperroom: #REF!
Name Late_Cancellation_Fee: #REF!
Name late_cancellation_fee1: #REF!
Name late_cancellation1: #REF!
Name Late_Cancellations: #REF!
Name late.cancellation: #REF!
Name late.cancellation.fee: #REF!
Name Marketing_Cost_per_day: #REF!
Name Marketing.costperday: #REF!
Name Marketing.costperroom: #REF!
Name No_of_Rooms: #REF!
Name no.of.rooms: #REF!
Name Number_of_Room_occupied: #REF!
Name number_of_walkins: #REF!
Name Number_of_walkins_accepted: #REF!
Name numberof.roomsoccupied: #REF!
Name numberof.walkinsaccepted: #REF!
Name Occupancy_Rate: #REF!
Name occupancyrate: #REF!
Name Overbooking_fee: #REF!
Name Overbooking_Rate: #REF!
Name overbooking_rate1: #REF!
Name Overbooking.fee: #REF!
Name overbooking.rate: #REF!
Name Room_Rate: #REF!
Name room_rate1: #REF!
Name room.rate: #REF!
Name Rooms_Overbooked: #REF!
Name roomsoverbooked: #REF!
Name Sales_Revenue_Per_day: #REF!
Name salesrevenue.perday: #REF!
Name sold.out: #REF!
Name Total_Cost_per_day: #REF!
Name Total_Profit: #REF!
Name Total.daily.profit: #REF!
Name Totalcost.perday: #REF!
Name Walk_Ins: #REF!
Name walk.ins: #REF!
Name walkin1: #REF!
Name Welcome_Pack_cost_per_room: #REF!
Name welcomepack.costperroom: #REF!

Sheet 1.a Manager's Page
A3: Stochastic inputs | C3: Desription and assumption
A4: S Input 1 | B4: Daily online reservations | C4: Number of booking requests made one day in advance. For a boutique costal property in peak season, it is assumed average advance reservation fill approximately 90% of capacity at baseline price of $150. Dependent on nightly room price. Price at $120 increases demand by 20%, and price at $120 decreases demand by 60%
A5: S Input 2 | B5: Late cancellations percentage | C5: Portions of thoese advance reservations that on or after their scheduled arrival date (no show). Late cancellations are assumed to average 15% of advance bookings but can vary from as low as 5% during reliable periods to as high as 25% when external disruptions occur
A6: S Input 3 | B6: Walk-in arrivals | C6: Guests arriving without a prior reservation. Walk-in arrivals are assumed at around a base of 3 per day, ranging from 0 when rooms sell out in advance to 8 or event-driven surge days
A7: S Input 4 | B7: Miscellaneuous daily expenses | C7: Unplanned operating costs such as last-minute maintenance, guest amenity requests, small repairs and emergency staff overtime. Ranging from $100 to $600 per day
A9: Decision variables | C9: Desription and assumption
A10: D Variable 1 | B10: Room nightly rate ($) | C10: Three tiered price points. Higher price -> higher revenue but may reduce bookings
A11: D Variable 2 | B11: Over-booking level | C11: Allows selling more than capacity to hedge against cancellations. Bumped guests incur compensation cost
A12: D Variable 3 | B12: Late-cancellation fee (%) | C12: Fee charged if guest cancels late. Offets some no-show lost; may reduce cancellations if fee > 0.
A14: Fixed inputs | C14: Desription and assumption
A15: F Input 1 | B15: Total rooms available | C15: Total one-bed unit at Coastal Nest with 20 rooms
A16: F Input 2 | B16: Housekeeping cost per occupied | C16: Deep turnover clean including 1.5 h of labor at $30/hr ($45) plus $5 for laundry, linens and consumables—reflective of boutique Airbnb‐style standards.
A17: F Input 3 | B17: Utilities cost per occupied room | C17: Average daily cost for electricity, water, Heating ventilation and air conditioning (HVAC) per occupied room
A18: F Input 4 | B18: Management and marketing fee per occupied room | C18: Allocated slice of on-site leadership and promotion spent per room-night. Assumption: There is one operation manager (100k AUD/year) and one marketing manager (110k AUD/year), with the marketing manager spending only 50% of time on Coastal Net Motel. Their combined allocated cost is approximately $425/day spreading over 20 rooms, which yields $21.25, rounded to $20.
A19: F Input 5 | B19: Check-in staff cost per day | C19: Covers 8 hours of front-desk/host time (morning check-out/check-in overlap + evening guest support) at $25/hour fully-loaded.
A21: CALCULATED VALUES | C21: Desription and assumption
A22: C Value 1 | B22: Net demand | C22: The total number of guests who actually show up and want a room on a given day. Assumption: - Some advance bookings cancel at the last minute (no-shows). - Walk-in guests then show up independently. Formula: Max(Daily Online Reservation - Round(Daily Online Reservation * Late Cancellation Portion,0),0) + Walk-in Arrivals
A23: C Value 2 | B23: Room sold | C23: How many rooms that the motel actually sells on a given day (including intentional over-booking). Capped by over-booking policy. Assumptions: - Never confirm more than Total room * (1 + Over-booking percentage) bookings. - Even if demand is higher, stop selling at that cap. Formula: Min(Net Demand, Round (Total Rooms * (1 + Over-booking level),0)
A24: C Value 3 | B24: Bumped guests | C24: The number of confirmed guest the motel must turn away or re-room because the motel over-booked and too many showed up. Assumption: - Physical limit is total number of room. - Anyone above the limit gets bumped and compensated. Formula: Max(Rooms Sold - Total Rooms, 0)
A25: C Value 4 | B25: Revenue from stays | C25: The income earned from rooms actually occupied Assumption: All paying guests (bookings that weren't bumped) pay the full nightly rate Formula: Room Sold x Room Nightly Rate
A26: C Value 5 | B26: Total compensation cost | C26: The expense of relocating or compensating guests the motel has bumped Assumptions: Every bumped guest gets exactly one night's Rom Nightly Rate in compensation Formula: Bumped Guests x Room Nightly Rate
A27: C Value 6 | B27: Total housekeeping cost | C27: The cost of cleaning and servicing each occupied room Assumptions: Unit house keeping cost is constant per occupied room. Only physical room (not bumped) incur this cost (up to Total room) Formula: Bumped Guests x Room Nightly Rate
A28: C Value 7 | B28: Total utilities cost | C28: Electricity, water, HVAC expenses per occupied room. Assumptions: Unit utilities cost applies per occupied room. Same occupancy basis as housekeeping Formula: Utilities Cost per Occupied Room x min(Net demand, total rooms)
A29: C Value 8 | B29: Total fixed inputs cost | C29: Sum of all day-to-day costs that vary with occupancy or bumping. Formula: Housekeeping Cost + Utilities cost + Compensation cost + Management and Marketing Fee + Miscellaneous expense
A30: C Value 9 | B30: Late no shows | C30: Number of advance booking that fail to materialise on arrival day. Formula: Round(Online Daily Booking * Late Cancellation Portions,0)
A31: C Value 10 | B31: Late cancellation fee revenue | C31: Penalty income from same-day cancellation (No-shows). Assumptions: Motel charges a percentage of the nightly rate on each no-show. This is separate from full room revenue. Formula: Late No Shows * Room Nightly Rate * Cancellation Fee
B33: OUTPUT
B34: Total Daily Profit | C34: The bottom-line profit for the day
B35: Sold Out: Yes/ No | C35: Yest if the Net Demand >= total rooms and over-booking sold out capcity; No otherwise
B38: General Assumption
B39: Length of stay per reservation | C39: Every booking covers exactly one night. Multi-night stays are not modelled
B40: Homogeneous rooms | C40: All rooms are identical in size, amenities, and nightly rate
B41: One-day booking lead time | C41: All advanced bookings occur exactly one day before arrival (no bookings further out)
B42: Instant cancellation | C42: Late cancellations occur on arrival day and immediately free up capacity for walk-ins
B43: Walk-ins only on no-show days | C43: Walk-in guest only fill the rooms freed by cancellations (or extra over-booking slots)
B44: No group or bulk bookings | C44: Every booking (in advance or walk-in) is for a single room
B45: Fixed housekeeping and utilities costs | C45: Each occupied room costs the same to clean and service, regardless of overall occupancy
B46: Compensation cost is equivalent to one night's rate | C46: Any bumped guest triggers the same compensation amount they are charged for one night
B47: No fixed overheads | C47: Only variable costs (housekeeping, utilities, compensation, misc. expenses) are modeled; fixed overheads (management salaries, property taxes) are excluded from daily profit

Sheet 1.b Model_Best estimates
G2: INPUTS
B3: CALCULATED VALUES & OUTPUT (DAILY) | C3: values | G3: Stochastic inputs | H3: values | L3: =G3 -> Stochastic inputs | M3: Worst Case | N3: Base Case | O3: Best Case
B4: ='1.a Manager''s Page'!B22 -> Net demand | C4: =ROUND(MAX(H4-ROUND(H4*H5,0),0)+H6,0) -> 18 | G4: ='1.a Manager''s Page'!B4 -> Daily online reservations | H4: {=ROUND(_xlfn.IFS(H16=120,18*1.2,H16=150,18,H16=180,18*0.4),0)} -> 18 | I4: Best guess | L4: =G4 -> Daily online reservations | M4: 7 bookings | N4: 18 bookings | O4: 22 bookings
B5: ='1.a Manager''s Page'!B23 -> Room sold | C5: =MIN(C4,ROUND(H24*(1+H17),0)) -> 18 | G5: ='1.a Manager''s Page'!B5 -> Late cancellations percentage | H5: 0.15 | I5: Best guess | L5: =G5 -> Late cancellations percentage | M5: 25% of bookings | N5: 15% bookings | O5: 5% bookings
B6: ='1.a Manager''s Page'!B24 -> Bumped guests | C6: =MAX(C5-H24,0) -> 0 | G6: ='1.a Manager''s Page'!B6 -> Walk-in arrivals | H6: 3 | I6: Best guess | L6: =G6 -> Walk-in arrivals | M6: 1 guests/day | N6: 3 guests/day | O6: 8 guests/day
B7: ='1.a Manager''s Page'!B25 -> Revenue from stays | C7: =C5*H16 -> 2700 | G7: ='1.a Manager''s Page'!B7 -> Miscellaneuous daily expenses | H7: 300 | I7: Best guess | L7: =G7 -> Miscellaneuous daily expenses | M7: $600/day | N7: $300/day | O7: $100/day
B8: ='1.a Manager''s Page'!B26 -> Total compensation cost | C8: =C6*H16 -> 0
B9: ='1.a Manager''s Page'!B27 -> Total housekeeping cost | C9: =H25*MIN(C5,H24) -> 900
B10: ='1.a Manager''s Page'!B28 -> Total utilities cost | C10: =H26*MIN(C4,H24) -> 270
B12: ='1.a Manager''s Page'!B29 -> Total fixed inputs cost | C12: =C8+C9+C10+H7+H28+H27 -> 2095
B13: ='1.a Manager''s Page'!B30 -> Late no shows | C13: =ROUND(H4*H5,0) -> 3
B14: ='1.a Manager''s Page'!B31 -> Late cancellation fee revenue | C14: =C13*H16*H18 -> 45
G15: Decision variables | H15: values
B16: OUTPUT | G16: ='1.a Manager''s Page'!B10 -> Room nightly rate ($) | H16: 150
B17: Total Daily Profit | C17: =C7+C14-C12 -> 650 | G17: ='1.a Manager''s Page'!B11 -> Over-booking level | H17: 0.1
B18: Sold Out: Yes/ No | C18: =IF(C5>=H24,"Yes","No") -> No | G18: ='1.a Manager''s Page'!B12 -> Late-cancellation fee (%) | H18: 0.1
G23: Fixed inputs | H23: values
G24: ='1.a Manager''s Page'!B15 -> Total rooms available | H24: 20
G25: ='1.a Manager''s Page'!B16 -> Housekeeping cost per occupied | H25: 50
G26: ='1.a Manager''s Page'!B17 -> Utilities cost per occupied room | H26: 15
G27: ='1.a Manager''s Page'!B18 -> Management and marketing fee per occupied room | H27: 425
G28: ='1.a Manager''s Page'!B19 -> Check-in staff cost per day | H28: 200

Sheet 1.c Model Simulated data
G2: INPUTS
B3: CALCULATED VALUES & OUTPUT (DAILY) | C3: values | G3: Stochastic inputs | H3: values
B4: ='1.a Manager''s Page'!B22 -> Net demand | C4: =ROUND(MAX(H4-ROUND(H4*H5,0),0)+H6,0) -> 13 | G4: ='1.a Manager''s Page'!B4 -> Daily online reservations | H4: {=_xlfn.IFS(H16=120,'3.b Probability Distributions'!D15,H16=150,'3.b Probability Distributions'!D16,H16=180,'3.b Probability Distributions'!D17)} -> 5.8277105
B5: ='1.a Manager''s Page'!B23 -> Room sold | C5: =MIN(C4,ROUND(H24*(1+H17),0)) -> 13 | G5: ='1.a Manager''s Page'!B5 -> Late cancellations percentage | H5: =VLOOKUP(RAND(),'3.b Probability Distributions'!$N$6:$P$10,3,TRUE) -> 0.25
B6: ='1.a Manager''s Page'!B24 -> Bumped guests | C6: =MAX(C5-H24,0) -> 0 | G6: ='1.a Manager''s Page'!B6 -> Walk-in arrivals | H6: =VLOOKUP(RAND(),'3.b Probability Distributions'!$X$6:$Z$16,3,TRUE) -> 8
B7: ='1.a Manager''s Page'!B25 -> Revenue from stays | C7: =C5*H16 -> 2340 | G7: ='1.a Manager''s Page'!B7 -> Miscellaneuous daily expenses | H7: =ROUND('3.b Probability Distributions'!AH9,0) -> 454
B8: ='1.a Manager''s Page'!B26 -> Total compensation cost | C8: =C6*H16 -> 0
B9: ='1.a Manager''s Page'!B27 -> Total housekeeping cost | C9: =H25*MIN(C5,H24) -> 650
B10: ='1.a Manager''s Page'!B28 -> Total utilities cost | C10: =H26*MIN(C4,H24) -> 195
B12: ='1.a Manager''s Page'!B29 -> Total fixed inputs cost | C12: =C8+C9+C10+H7+H28+H27 -> 1924
B13: ='1.a Manager''s Page'!B30 -> Late no shows | C13: =ROUND(H4*H5,0) -> 1
B14: ='1.a Manager''s Page'!B31 -> Late cancellation fee revenue | C14: =C13*H16*H18 -> 18
G15: Decision variables | H15: values
B16: OUTPUT | G16: ='1.a Manager''s Page'!B10 -> Room nightly rate ($) | H16: 180
B17: Total Daily Profit | C17: =C7+C14-C12 -> 434 | G17: ='1.a Manager''s Page'!B11 -> Over-booking level | H17: 0.1
B18: Sold Out: Yes/ No | C18: =IF(C5>=H24,"Yes","No") -> No | G18: ='1.a Manager''s Page'!B12 -> Late-cancellation fee (%) | H18: 0.1
G23: Fixed inputs | H23: values
G24: ='1.a Manager''s Page'!B15 -> Total rooms available | H24: 20
G25: ='1.a Manager''s Page'!B16 -> Housekeeping cost per occupied | H25: 50
G26: ='1.a Manager''s Page'!B17 -> Utilities cost per occupied room | H26: 15
G27: ='1.a Manager''s Page'!B18 -> Management and marketing fee per occupied room | H27: 425
G28: ='1.a Manager''s Page'!B19 -> Check-in staff cost per day | H28: 200

Sheet 2.a.1 Scenario for S input 1
B1: ='1.b Model_Best estimates'!G16 -> Room nightly rate ($) | C1: 120 | I1: ='1.b Model_Best estimates'!G16 -> Room nightly rate ($) | K1: 150 | P1: ='1.b Model_Best estimates'!G16 -> Room nightly rate ($) | R1: 180
B2: Scenario Summary | I2: Scenario Summary | P2: Scenario Summary
D3: Current Values: | E3: Best Case | F3: Base Case | G3: Worst Case | K3: Current Values: | L3: Best Case | M3: Base Case | N3: Worst Case | R3: Current Values: | S3: Best Case | T3: Base Case | U3: Worst Case
E4: Created by Microsoft Office User on 5/19/2025 Modified by BA HUY HOANG LE on 21/05/2025 | F4: Created by Microsoft Office User on 5/19/2025 Modified by BA HUY HOANG LE on 21/05/2025 | G4: Created by Microsoft Office User on 5/19/2025 Modified by BA HUY HOANG LE on 21/05/2025 | L4: Created by Microsoft Office User on 5/19/2025 Modified by BA HUY HOANG LE on 21/05/2025 | M4: Created by Microsoft Office User on 5/19/2025 Modified by BA HUY HOANG LE on 21/05/2025 | N4: Created by Microsoft Office User on 5/19/2025 Modified by BA HUY HOANG LE on 21/05/2025 | S4: Created by Microsoft Office User on 5/19/2025 Modified by BA HUY HOANG LE on 21/05/2025 | T4: Created by Microsoft Office User on 5/19/2025 Modified by BA HUY HOANG LE on 21/05/2025 | U4: Created by Microsoft Office User on 5/19/2025 Modified by BA HUY HOANG LE on 21/05/2025
B5: Changing Cells: | I5: Changing Cells: | P5: Changing Cells:
C6: ='1.b Model_Best estimates'!G4 -> Daily online reservations | D6: 18 | E6: 22 | F6: 18 | G6: 7 | J6: ='1.b Model_Best estimates'!G4 -> Daily online reservations | K6: 18 | L6: 22 | M6: 18 | N6: 7 | Q6: ='1.b Model_Best estimates'!G4 -> Daily online reservations | R6: 18 | S6: 22 | T6: 18 | U6: 7
B7: Result Cells: | I7: Result Cells: | P7: Result Cells:
C8: ='1.b Model_Best estimates'!B17 -> Total Daily Profit | D8: 211 | E8: 211 | F8: 211 | G8: -143 | J8: ='1.b Model_Best estimates'!B17 -> Total Daily Profit | K8: 735 | L8: 820 | M8: 735 | N8: -60 | Q8: ='1.b Model_Best estimates'!B17 -> Total Daily Profit | R8: 969 | S8: 1429 | T8: 969 | U8: -102
B13: ='1.b Model_Best estimates'!G16 -> Room nightly rate ($) | C13: 120 | I13: ='1.b Model_Best estimates'!G16 -> Room nightly rate ($) | K13: 150 | P13: ='1.b Model_Best estimates'!G16 -> Room nightly rate ($) | R13: 180
B14: Scenario Summary | I14: Scenario Summary | P14: Scenario Summary
D15: Current Values: | E15: Best Case | F15: Base Case | G15: Worst Case | K15: Current Values: | L15: Best Case | M15: Base Case | N15: Worst Case | R15: Current Values: | S15: Best Case | T15: Base Case | U15: Worst Case
B16: Changing Cells: | I16: Changing Cells: | P16: Changing Cells:
C17: ='1.b Model_Best estimates'!G4 -> Daily online reservations | D17: 18 | E17: 22 | F17: 18 | G17: 7 | J17: ='1.b Model_Best estimates'!G4 -> Daily online reservations | K17: 18 | L17: 22 | M17: 18 | N17: 7 | Q17: ='1.b Model_Best estimates'!G4 -> Daily online reservations | R17: 18 | S17: 22 | T17: 18 | U17: 7
B18: Result Cells: | I18: Result Cells: | P18: Result Cells:
C19: ='1.b Model_Best estimates'!B18 -> Sold Out: Yes/ No | D19: Yes | E19: Yes | F19: Yes | G19: No | J19: ='1.b Model_Best estimates'!B18 -> Sold Out: Yes/ No | K19: No | L19: Yes | M19: No | N19: No | Q19: ='1.b Model_Best estimates'!B18 -> Sold Out: Yes/ No | R19: No | S19: Yes | T19: No | U19: No

Sheet 2.a.2 Scenario for S input 2
B1: ='1.b Model_Best estimates'!G16 -> Room nightly rate ($) | C1: 120 | I1: ='1.b Model_Best estimates'!G16 -> Room nightly rate ($) | J1: 150 | P1: ='1.b Model_Best estimates'!G16 -> Room nightly rate ($) | Q1: 180
B2: Scenario Summary | I2: Scenario Summary | P2: Scenario Summary
D3: Current Values: | E3: Best Case | F3: Base Case | G3: Worst Case | K3: Current Values: | L3: Best Case | M3: Base Case | N3: Worst Case | R3: Current Values: | S3: Best Case | T3: Base Case | U3: Worst Case
E4: Created by Microsoft Office User on 5/19/2025 Modified by BA HUY HOANG LE on 21/05/2025 | F4: Created by Microsoft Office User on 5/19/2025 Modified by BA HUY HOANG LE on 21/05/2025 | G4: Created by Microsoft Office User on 5/19/2025 Modified by BA HUY HOANG LE on 21/05/2025 | L4: Created by Microsoft Office User on 5/19/2025 Modified by BA HUY HOANG LE on 21/05/2025 | M4: Created by Microsoft Office User on 5/19/2025 Modified by BA HUY HOANG LE on 21/05/2025 | N4: Created by Microsoft Office User on 5/19/2025 Modified by BA HUY HOANG LE on 21/05/2025 | S4: Created by Microsoft Office User on 5/19/2025 Modified by BA HUY HOANG LE on 21/05/2025 | T4: Created by Microsoft Office User on 5/19/2025 Modified by BA HUY HOANG LE on 21/05/2025 | U4: Created by Microsoft Office User on 5/19/2025 Modified by BA HUY HOANG LE on 21/05/2025
B5: Changing Cells: | I5: Changing Cells: | P5: Changing Cells:
C6: ='1.b Model_Best estimates'!G5 -> Late cancellations percentage | D6: 0.15 | E6: 0.05 | F6: 0.15 | G6: 0.25 | J6: ='1.b Model_Best estimates'!G5 -> Late cancellations percentage | K6: 0.15 | L6: 0.05 | M6: 0.15 | N6: 0.25 | Q6: ='1.b Model_Best estimates'!G5 -> Late cancellations percentage | R6: 0.15 | S6: 0.05 | T6: 0.15 | U6: 0.25
B7: Result Cells: | I7: Result Cells: | P7: Result Cells:
C8: ='1.b Model_Best estimates'!B17 -> Total Daily Profit | D8: 211 | E8: 187 | F8: 211 | G8: 235 | J8: ='1.b Model_Best estimates'!B17 -> Total Daily Profit | K8: 735 | L8: 790 | M8: 735 | N8: 595 | Q8: ='1.b Model_Best estimates'!B17 -> Total Daily Profit | R8: -102 | S8: -5 | T8: -102 | U8: -199
B13: ='1.b Model_Best estimates'!G16 -> Room nightly rate ($) | C13: 120 | I13: ='1.b Model_Best estimates'!G16 -> Room nightly rate ($) | J13: 150 | P13: ='1.b Model_Best estimates'!G16 -> Room nightly rate ($) | Q13: 180
B14: Scenario Summary | I14: Scenario Summary | P14: Scenario Summary
D15: Current Values: | E15: Best Case | F15: Base Case | G15: Worst Case | K15: Current Values: | L15: Best Case | M15: Base Case | N15: Worst Case | R15: Current Values: | S15: Best Case | T15: Base Case | U15: Worst Case
B16: Changing Cells: | I16: Changing Cells: | P16: Changing Cells:
C17: ='1.b Model_Best estimates'!G5 -> Late cancellations percentage | D17: 0.15 | E17: 0.05 | F17: 0.15 | G17: 0.25 | J17: ='1.b Model_Best estimates'!G5 -> Late cancellations percentage | K17: 0.15 | L17: 0.05 | M17: 0.15 | N17: 0.25 | Q17: ='1.b Model_Best estimates'!G5 -> Late cancellations percentage | R17: 0.15 | S17: 0.05 | T17: 0.15 | U17: 0.25
B18: Result Cells: | I18: Result Cells: | P18: Result Cells:
C19: ='1.b Model_Best estimates'!B18 -> Sold Out: Yes/ No | D19: Yes | E19: Yes | F19: Yes | G19: Yes | J19: ='1.b Model_Best estimates'!B18 -> Sold Out: Yes/ No | K19: No | L19: Yes | M19: No | N19: No | Q19: ='1.b Model_Best estimates'!B18 -> Sold Out: Yes/ No | R19: No | S19: No | T19: No | U19: No

Sheet 2.a.3 Scenario for S input 3
B1: ='1.b Model_Best estimates'!G16 -> Room nightly rate ($) | C1: 120 | I1: ='1.b Model_Best estimates'!G16 -> Room nightly rate ($) | J1: 150 | P1: ='1.b Model_Best estimates'!G16 -> Room nightly rate ($) | Q1: 180
B2: Scenario Summary | I2: Scenario Summary | P2: Scenario Summary
D3: Current Values: | E3: Best Case | F3: Base Case | G3: Worst Case | K3: Current Values: | L3: Best Case | M3: Base Case | N3: Worst Case | R3: Current Values: | S3: Best Case | T3: Base Case | U3: Worst Case
E4: Created by Microsoft Office User on 5/19/2025 Modified by BA HUY HOANG LE on 21/05/2025 | F4: Created by Microsoft Office User on 5/19/2025 Modified by BA HUY HOANG LE on 21/05/2025 | G4: Created by Microsoft Office User on 5/19/2025 Modified by BA HUY HOANG LE on 21/05/2025 | L4: Created by Microsoft Office User on 5/19/2025 Modified by BA HUY HOANG LE on 21/05/2025 | M4: Created by Microsoft Office User on 5/19/2025 Modified by BA HUY HOANG LE on 21/05/2025 | N4: Created by Microsoft Office User on 5/19/2025 Modified by BA HUY HOANG LE on 21/05/2025 | S4: Created by Microsoft Office User on 5/19/2025 Modified by BA HUY HOANG LE on 21/05/2025 | T4: Created by Microsoft Office User on 5/19/2025 Modified by BA HUY HOANG LE on 21/05/2025 | U4: Created by Microsoft Office User on 5/19/2025 Modified by BA HUY HOANG LE on 21/05/2025
B5: Changing Cells: | I5: Changing Cells: | P5: Changing Cells:
C6: ='1.b Model_Best estimates'!G6 -> Walk-in arrivals | D6: 8 | E6: 8 | F6: 3 | G6: 1 | J6: ='1.b Model_Best estimates'!G6 -> Walk-in arrivals | K6: 8 | L6: 8 | M6: 3 | N6: 1 | Q6: ='1.b Model_Best estimates'!G6 -> Walk-in arrivals | R6: 8 | S6: 8 | T6: 3 | U6: 1
B7: Result Cells: | I7: Result Cells: | P7: Result Cells:
C8: ='1.b Model_Best estimates'!B17 -> Total Daily Profit | D8: 211 | E8: 211 | F8: 211 | G8: 211 | J8: ='1.b Model_Best estimates'!B17 -> Total Daily Profit | K8: 820 | L8: 820 | M8: 650 | N8: 480 | Q8: ='1.b Model_Best estimates'!B17 -> Total Daily Profit | R8: 703 | S8: 703 | T8: 128 | U8: -102
B13: ='1.b Model_Best estimates'!G16 -> Room nightly rate ($) | C13: 120 | I13: ='1.b Model_Best estimates'!G16 -> Room nightly rate ($) | J13: 150 | P13: ='1.b Model_Best estimates'!G16 -> Room nightly rate ($) | Q13: 180
B14: Scenario Summary | I14: Scenario Summary | P14: Scenario Summary
D15: Current Values: | E15: Best Case | F15: Base Case | G15: Worst Case | K15: Current Values: | L15: Best Case | M15: Base Case | N15: Worst Case | R15: Current Values: | S15: Best Case | T15: Base Case | U15: Worst Case
B16: Changing Cells: | I16: Changing Cells: | P16: Changing Cells:
C17: ='1.b Model_Best estimates'!G6 -> Walk-in arrivals | D17: 8 | E17: 8 | F17: 3 | G17: 1 | J17: ='1.b Model_Best estimates'!G6 -> Walk-in arrivals | K17: 8 | L17: 8 | M17: 3 | N17: 1 | Q17: ='1.b Model_Best estimates'!G6 -> Walk-in arrivals | R17: 8 | S17: 8 | T17: 3 | U17: 1
B18: Result Cells: | I18: Result Cells: | P18: Result Cells:
C19: ='1.b Model_Best estimates'!B18 -> Sold Out: Yes/ No | D19: Yes | E19: Yes | F19: Yes | G19: Yes | J19: ='1.b Model_Best estimates'!B18 -> Sold Out: Yes/ No | K19: Yes | L19: Yes | M19: No | N19: No | Q19: ='1.b Model_Best estimates'!B18 -> Sold Out: Yes/ No | R19: No | S19: No | T19: No | U19: No

Sheet 2.a.4 Scenario for S input  4
B1: ='1.b Model_Best estimates'!G16 -> Room nightly rate ($) | C1: 120 | I1: ='1.b Model_Best estimates'!G16 -> Room nightly rate ($) | J1: 150 | P1: ='1.b Model_Best estimates'!G16 -> Room nightly rate ($) | Q1: 180
B2: Scenario Summary | I2: Scenario Summary | P2: Scenario Summary
D3: Current Values: | E3: Best Case | F3: Base Case | G3: Worst Case | K3: Current Values: | L3: Best Case | M3: Base Case | N3: Worst Case | R3: Current Values: | S3: Best Case | T3: Base Case | U3: Worst Case
E4: Created by Microsoft Office User on 5/19/2025 Modified by BA HUY HOANG LE on 21/05/2025 | F4: Created by Microsoft Office User on 5/19/2025 Modified by BA HUY HOANG LE on 21/05/2025 | G4: Created by Microsoft Office User on 5/19/2025 Modified by BA HUY HOANG LE on 21/05/2025 | L4: Created by Microsoft Office User on 5/19/2025 Modified by BA HUY HOANG LE on 21/05/2025 | M4: Created by Microsoft Office User on 5/19/2025 Modified by BA HUY HOANG LE on 21/05/2025 | N4: Created by Microsoft Office User on 5/19/2025 Modified by BA HUY HOANG LE on 21/05/2025 | S4: Created by Microsoft Office User on 5/19/2025 Modified by BA HUY HOANG LE on 21/05/2025 | T4: Created by Microsoft Office User on 5/19/2025 Modified by BA HUY HOANG LE on 21/05/2025 | U4: Created by Microsoft Office User on 5/19/2025 Modified by BA HUY HOANG LE on 21/05/2025
B5: Changing Cells: | I5: Changing Cells: | P5: Changing Cells:
C6: ='1.b Model_Best estimates'!G7 -> Miscellaneuous daily expenses | D6: 300 | E6: 100 | F6: 300 | G6: 600 | J6: ='1.b Model_Best estimates'!G7 -> Miscellaneuous daily expenses | K6: 300 | L6: 100 | M6: 300 | N6: 600 | Q6: ='1.b Model_Best estimates'!G7 -> Miscellaneuous daily expenses | R6: 300 | S6: 100 | T6: 300 | U6: 600
B7: Result Cells: | I7: Result Cells: | P7: Result Cells:
C8: ='1.b Model_Best estimates'!B17 -> Total Daily Profit | D8: 211 | E8: 411 | F8: 211 | G8: -89 | J8: ='1.b Model_Best estimates'!B17 -> Total Daily Profit | K8: 650 | L8: 850 | M8: 650 | N8: 350 | Q8: ='1.b Model_Best estimates'!B17 -> Total Daily Profit | R8: 128 | S8: 328 | T8: 128 | U8: -172
B13: ='1.b Model_Best estimates'!G16 -> Room nightly rate ($) | C13: 120 | I13: ='1.b Model_Best estimates'!G16 -> Room nightly rate ($) | J13: 150 | P13: ='1.b Model_Best estimates'!G16 -> Room nightly rate ($) | Q13: 180
B14: Scenario Summary | I14: Scenario Summary | P14: Scenario Summary
D15: Current Values: | E15: Best Case | F15: Base Case | G15: Worst Case | K15: Current Values: | L15: Best Case | M15: Base Case | N15: Worst Case | R15: Current Values: | S15: Best Case | T15: Base Case | U15: Worst Case
B16: Changing Cells: | I16: Changing Cells: | P16: Changing Cells:
C17: ='1.b Model_Best estimates'!G7 -> Miscellaneuous daily expenses | D17: 300 | E17: 100 | F17: 300 | G17: 600 | J17: ='1.b Model_Best estimates'!G7 -> Miscellaneuous daily expenses | K17: 300 | L17: 100 | M17: 300 | N17: 600 | Q17: ='1.b Model_Best estimates'!G7 -> Miscellaneuous daily expenses | R17: 300 | S17: 100 | T17: 300 | U17: 600
B18: Result Cells: | I18: Result Cells: | P18: Result Cells:
C19: ='1.b Model_Best estimates'!B18 -> Sold Out: Yes/ No | D19: Yes | E19: Yes | F19: Yes | G19: Yes | J19: ='1.b Model_Best estimates'!B18 -> Sold Out: Yes/ No | K19: No | L19: No | M19: No | N19: No | Q19: ='1.b Model_Best estimates'!B18 -> Sold Out: Yes/ No | R19: No | S19: No | T19: No | U19: No

Sheet 2.bSummary of Scenario analysis
B1: Nightly Room Rate $120 | J1: Nightly Room Rate $150 | R1: Nightlt Room Rate $180
B2: Scenarios | C2: Best | D2: Base | E2: Worst | J2: =B2 -> Scenarios | K2: =C2 -> Best | L2: =D2 -> Base | M2: =E2 -> Worst | R2: =B2 -> Scenarios | S2: =C2 -> Best | T2: =D2 -> Base | U2: =E2 -> Worst
A4: changing cell | B4: ='1.b Model_Best estimates'!G4 -> Daily online reservations | C4: ='2.a.1 Scenario for S input 1'!E6 -> 22 | D4: ='2.a.1 Scenario for S input 1'!F6 -> 18 | E4: ='2.a.1 Scenario for S input 1'!G6 -> 7 | I4: changing cell | J4: ='1.b Model_Best estimates'!G4 -> Daily online reservations | K4: ='2.a.1 Scenario for S input 1'!L6 -> 22 | L4: ='2.a.1 Scenario for S input 1'!M6 -> 18 | M4: ='2.a.1 Scenario for S input 1'!N6 -> 7 | Q4: changing cell | R4: ='1.b Model_Best estimates'!G4 -> Daily online reservations | S4: ='2.a.1 Scenario for S input 1'!S6 -> 22 | T4: ='2.a.1 Scenario for S input 1'!T6 -> 18 | U4: ='2.a.1 Scenario for S input 1'!U6 -> 7
A5: Output result | B5: ='1.b Model_Best estimates'!B17 -> Total Daily Profit | C5: ='2.a.1 Scenario for S input 1'!E8 -> 211 | D5: ='2.a.1 Scenario for S input 1'!F8 -> 211 | E5: ='2.a.1 Scenario for S input 1'!G8 -> -143 | I5: Output result | J5: ='1.b Model_Best estimates'!B17 -> Total Daily Profit | K5: ='2.a.1 Scenario for S input 1'!L8 -> 820 | L5: ='2.a.1 Scenario for S input 1'!M8 -> 735 | M5: ='2.a.1 Scenario for S input 1'!N8 -> -60 | Q5: Output result | R5: ='1.b Model_Best estimates'!B17 -> Total Daily Profit | S5: ='2.a.1 Scenario for S input 1'!S8 -> 1429 | T5: ='2.a.1 Scenario for S input 1'!T8 -> 969 | U5: ='2.a.1 Scenario for S input 1'!U8 -> -102
B6: ='1.b Model_Best estimates'!B18 -> Sold Out: Yes/ No | C6: ='2.a.1 Scenario for S input 1'!E19 -> Yes | D6: ='2.a.1 Scenario for S input 1'!F19 -> Yes | E6: ='2.a.1 Scenario for S input 1'!G19 -> No | J6: ='1.b Model_Best estimates'!B18 -> Sold Out: Yes/ No | K6: ='2.a.1 Scenario for S input 1'!L19 -> Yes | L6: ='2.a.1 Scenario for S input 1'!M19 -> No | M6: ='2.a.1 Scenario for S input 1'!N19 -> No | R6: ='1.b Model_Best estimates'!B18 -> Sold Out: Yes/ No | S6: ='2.a.1 Scenario for S input 1'!S19 -> Yes | T6: ='2.a.1 Scenario for S input 1'!T19 -> No | U6: ='2.a.1 Scenario for S input 1'!U19 -> No
A8: changing cell | B8: ='1.b Model_Best estimates'!G5 -> Late cancellations percentage | C8: ='2.a.2 Scenario for S input 2'!E6 -> 0.05 | D8: ='2.a.2 Scenario for S input 2'!F6 -> 0.15 | E8: ='2.a.2 Scenario for S input 2'!G6 -> 0.25 | I8: changing cell | J8: ='1.b Model_Best estimates'!G5 -> Late cancellations percentage | K8: ='2.a.2 Scenario for S input 2'!L6 -> 0.05 | L8: ='2.a.2 Scenario for S input 2'!M6 -> 0.15 | M8: ='2.a.2 Scenario for S input 2'!N6 -> 0.25 | Q8: changing cell | R8: ='1.b Model_Best estimates'!G5 -> Late cancellations percentage | S8: ='2.a.2 Scenario for S input 2'!S6 -> 0.05 | T8: ='2.a.2 Scenario for S input 2'!T6 -> 0.15 | U8: ='2.a.2 Scenario for S input 2'!U6 -> 0.25
A9: Output result | B9: ='1.b Model_Best estimates'!B17 -> Total Daily Profit | C9: ='2.a.2 Scenario for S input 2'!E8 -> 187 | D9: ='2.a.2 Scenario for S input 2'!F8 -> 211 | E9: ='2.a.2 Scenario for S input 2'!G8 -> 235 | I9: Output result | J9: ='1.b Model_Best estimates'!B17 -> Total Daily Profit | K9: ='2.a.2 Scenario for S input 2'!L8 -> 790 | L9: ='2.a.2 Scenario for S input 2'!M8 -> 735 | M9: ='2.a.2 Scenario for S input 2'!N8 -> 595 | Q9: Output result | R9: ='1.b Model_Best estimates'!B17 -> Total Daily Profit | S9: ='2.a.2 Scenario for S input 2'!S8 -> -5 | T9: ='2.a.2 Scenario for S input 2'!T8 -> -102 | U9: ='2.a.2 Scenario for S input 2'!U8 -> -199
B10: ='1.b Model_Best estimates'!B18 -> Sold Out: Yes/ No | C10: ='2.a.2 Scenario for S input 2'!E19 -> Yes | D10: ='2.a.2 Scenario for S input 2'!F19 -> Yes | E10: ='2.a.2 Scenario for S input 2'!G19 -> Yes | J10: ='1.b Model_Best estimates'!B18 -> Sold Out: Yes/ No | K10: ='2.a.2 Scenario for S input 2'!L19 -> Yes | L10: ='2.a.2 Scenario for S input 2'!M19 -> No | M10: ='2.a.2 Scenario for S input 2'!N19 -> No | R10: ='1.b Model_Best estimates'!B18 -> Sold Out: Yes/ No | S10: ='2.a.2 Scenario for S input 2'!S19 -> No | T10: ='2.a.2 Scenario for S input 2'!T19 -> No | U10: ='2.a.2 Scenario for S input 2'!U19 -> No
A12: changing cell | B12: ='1.b Model_Best estimates'!G6 -> Walk-in arrivals | C12: ='2.a.3 Scenario for S input 3'!L6 -> 8 | D12: ='2.a.3 Scenario for S input 3'!M6 -> 3 | E12: ='2.a.3 Scenario for S input 3'!N6 -> 1 | I12: changing cell | J12: ='1.b Model_Best estimates'!G6 -> Walk-in arrivals | K12: ='2.a.3 Scenario for S input 3'!L6 -> 8 | L12: ='2.a.3 Scenario for S input 3'!M6 -> 3 | M12: ='2.a.3 Scenario for S input 3'!N6 -> 1 | Q12: changing cell | R12: ='1.b Model_Best estimates'!G6 -> Walk-in arrivals | S12: ='2.a.3 Scenario for S input 3'!S6 -> 8 | T12: ='2.a.3 Scenario for S input 3'!T6 -> 3 | U12: ='2.a.3 Scenario for S input 3'!U6 -> 1
A13: Output result | B13: ='1.b Model_Best estimates'!B17 -> Total Daily Profit | C13: ='2.a.3 Scenario for S input 3'!E8 -> 211 | D13: ='2.a.3 Scenario for S input 3'!F8 -> 211 | E13: ='2.a.3 Scenario for S input 3'!G8 -> 211 | I13: Output result | J13: ='1.b Model_Best estimates'!B17 -> Total Daily Profit | K13: ='2.a.3 Scenario for S input 3'!L8 -> 820 | L13: ='2.a.3 Scenario for S input 3'!M8 -> 650 | M13: ='2.a.3 Scenario for S input 3'!N8 -> 480 | Q13: Output result | R13: ='1.b Model_Best estimates'!B17 -> Total Daily Profit | S13: ='2.a.3 Scenario for S input 3'!S8 -> 703 | T13: ='2.a.3 Scenario for S input 3'!T8 -> 128 | U13: ='2.a.3 Scenario for S input 3'!U8 -> -102
B14: ='1.b Model_Best estimates'!B18 -> Sold Out: Yes/ No | C14: ='2.a.3 Scenario for S input 3'!E19 -> Yes | D14: ='2.a.3 Scenario for S input 3'!F19 -> Yes | E14: ='2.a.3 Scenario for S input 3'!G19 -> Yes | J14: ='1.b Model_Best estimates'!B18 -> Sold Out: Yes/ No | K14: ='2.a.3 Scenario for S input 3'!L19 -> Yes | L14: ='2.a.3 Scenario for S input 3'!M19 -> No | M14: ='2.a.3 Scenario for S input 3'!N19 -> No | R14: ='1.b Model_Best estimates'!B18 -> Sold Out: Yes/ No | S14: ='2.a.3 Scenario for S input 3'!S19 -> No | T14: ='2.a.3 Scenario for S input 3'!T19 -> No | U14: ='2.a.3 Scenario for S input 3'!U19 -> No
A16: changing cell | B16: ='2.a.4 Scenario for S input 4'!J6 -> Miscellaneuous daily expenses | C16: ='2.a.4 Scenario for S input 4'!L6 -> 100 | D16: ='2.a.4 Scenario for S input 4'!M6 -> 300 | E16: ='2.a.4 Scenario for S input 4'!N6 -> 600 | I16: changing cell | J16: ='2.a.4 Scenario for S input 4'!J6 -> Miscellaneuous daily expenses | K16: ='2.a.4 Scenario for S input 4'!L6 -> 100 | L16: ='2.a.4 Scenario for S input 4'!M6 -> 300 | M16: ='2.a.4 Scenario for S input 4'!N6 -> 600 | Q16: changing cell | R16: ='2.a.4 Scenario for S input 4'!J6 -> Miscellaneuous daily expenses | S16: ='2.a.4 Scenario for S input 4'!S17 -> 100 | T16: ='2.a.4 Scenario for S input 4'!T17 -> 300 | U16: ='2.a.4 Scenario for S input 4'!U17 -> 600
A17: Output result | B17: ='1.b Model_Best estimates'!B17 -> Total Daily Profit | C17: ='2.a.4 Scenario for S input 4'!E8 -> 411 | D17: ='2.a.4 Scenario for S input 4'!F8 -> 211 | E17: ='2.a.4 Scenario for S input 4'!G8 -> -89 | I17: Output result | J17: ='1.b Model_Best estimates'!B17 -> Total Daily Profit | K17: ='2.a.4 Scenario for S input 4'!L8 -> 850 | L17: ='2.a.4 Scenario for S input 4'!M8 -> 650 | M17: ='2.a.4 Scenario for S input 4'!N8 -> 350 | Q17: Output result | R17: ='1.b Model_Best estimates'!B17 -> Total Daily Profit | S17: {='2.a.4 Scenario for S input 4'!S8:U8} -> 328 | T17: 128 | U17: -172
B18: ='1.b Model_Best estimates'!B18 -> Sold Out: Yes/ No | C18: ='2.a.4 Scenario for S input 4'!E19 -> Yes | D18: ='2.a.4 Scenario for S input 4'!F19 -> Yes | E18: ='2.a.4 Scenario for S input 4'!G19 -> Yes | J18: ='1.b Model_Best estimates'!B18 -> Sold Out: Yes/ No | K18: ='2.a.4 Scenario for S input 4'!L19 -> No | L18: ='2.a.4 Scenario for S input 4'!M19 -> No | M18: ='2.a.4 Scenario for S input 4'!N19 -> No | R18: ='1.b Model_Best estimates'!B18 -> Sold Out: Yes/ No | S18: ='2.a.4 Scenario for S input 4'!S19 -> No | T18: ='2.a.4 Scenario for S input 4'!T19 -> No | U18: ='2.a.4 Scenario for S input 4'!U19 -> No

Sheet 3.a Observed Data
A1: S Input 1 - Daily Online Reservation | K1: S Input 2 - Late Cancellation Percentage | T1: S Input 3 - Walk-in Arrivals | AH1: S Input 4 - Miscellaneous Daily Expenses
A2: Dates when room rate $120 | D2: Dates when room rate $150 | G2: Dates when room rate $180
A3: Date | B3: ='1.a Manager''s Page'!B4 -> Daily online reservations | D3: Date | E3: ='1.a Manager''s Page'!B4 -> Daily online reservations | G3: Date | H3: ='1.a Manager''s Page'!B4 -> Daily online reservations | L3: Date | M3: ='1.a Manager''s Page'!B5 -> Late cancellations percentage | O3: ='1.a Manager''s Page'!B5 -> Late cancellations percentage | P3: Probability of Late cancellation percentage | Q3: Probability of Late cancellation percentage (%) | U3: Date | V3: ='1.a Manager''s Page'!B6 -> Walk-in arrivals | X3: ='1.a Manager''s Page'!B6 -> Walk-in arrivals | Y3: Count of walk-in arrivals | Z3: Count of walk-in arrivals (%)
A4: 44900 | B4: 19.760588 | D4: 44896 | E4: 19 | G4: 44897 | H4: 7 | L4: 44896 | M4: 0.1 | O4: 0.05 | P4: =COUNTIF($L$4:$M$274,O4) -> 73 | Q4: =P4/$P$9 -> 0.26937269 | U4: 44896 | V4: 3 | X4: 0 | Y4: =COUNTIF($U$4:$V$274,X4) -> 15 | Z4: =Y4/$Y$15 -> 0.055350554
A5: 44901 | B5: 19.500679 | D5: 44899 | E5: 18 | G5: 44898 | H5: 8 | L5: 44897 | M5: 0.25 | O5: 0.1 | P5: =COUNTIF($L$4:$M$274,O5) -> 52 | Q5: =P5/$P$9 -> 0.19188192 | U5: 44897 | V5: 10 | X5: 1 | Y5: =COUNTIF($U$4:$V$274,X5) -> 45 | Z5: =Y5/$Y$15 -> 0.16605166
A6: 44902 | B6: 21.282195 | D6: 44904 | E6: 20 | G6: 44903 | H6: 9 | L6: 44898 | M6: 0.15 | O6: 0.15 | P6: =COUNTIF($L$4:$M$274,O6) -> 78 | Q6: =P6/$P$9 -> 0.28782288 | U6: 44898 | V6: 6 | X6: 2 | Y6: =COUNTIF($U$4:$V$274,X6) -> 27 | Z6: =Y6/$Y$15 -> 0.099630996
A7: 44906 | B7: 22.557497 | D7: 44913 | E7: 15 | G7: 44905 | H7: 6 | L7: 44899 | M7: 0.15 | O7: 0.2 | P7: =COUNTIF($L$4:$M$274,O7) -> 40 | Q7: =P7/$P$9 -> 0.14760148 | U7: 44899 | V7: 3 | X7: 3 | Y7: =COUNTIF($U$4:$V$274,X7) -> 72 | Z7: =Y7/$Y$15 -> 0.26568266
A8: 44909 | B8: 23.993725 | D8: 44914 | E8: 16 | G8: 44907 | H8: 7 | L8: 44900 | M8: 0.05 | O8: 0.25 | P8: =COUNTIF($L$4:$M$274,O8) -> 28 | Q8: =P8/$P$9 -> 0.10332103 | U8: 44900 | V8: 1 | X8: 4 | Y8: =COUNTIF($U$4:$V$274,X8) -> 24 | Z8: =Y8/$Y$15 -> 0.088560886
A9: 44910 | B9: 27.69205 | D9: 44916 | E9: 18 | G9: 44908 | H9: 6 | L9: 44901 | M9: 0.05 | P9: =COUNT(M4:M274) -> 271 | Q9: =SUM(Q4:Q8) -> 1 | R9: Total | U9: 44901 | V9: 1 | X9: 5 | Y9: =COUNTIF($U$4:$V$274,X9) -> 6 | Z9: =Y9/$Y$15 -> 0.022140221
A10: 44911 | B10: 18.620041 | D10: 44919 | E10: 15 | G10: 44921 | H10: 7 | L10: 44902 | M10: 0.05 | U10: 44902 | V10: 1 | X10: 6 | Y10: =COUNTIF($U$4:$V$274,X10) -> 14 | Z10: =Y10/$Y$15 -> 0.051660517
A11: 44912 | B11: 21.791309 | D11: 44920 | E11: 19 | G11: 44929 | H11: 6 | L11: 44903 | M11: 0.2 | U11: 44903 | V11: 8 | X11: 7 | Y11: =COUNTIF($U$4:$V$274,X11) -> 10 | Z11: =Y11/$Y$15 -> 0.036900369
A12: 44915 | B12: 19.75144 | D12: 44923 | E12: 16 | G12: 44930 | H12: 8 | L12: 44904 | M12: 0.15 | U12: 44904 | V12: 4 | X12: 8 | Y12: =COUNTIF($U$4:$V$274,X12) -> 30 | Z12: =Y12/$Y$15 -> 0.11070111
A13: 44917 | B13: 22.654604 | D13: 44924 | E13: 16 | G13: 44931 | H13: 8 | L13: 44905 | M13: 0.15 | U13: 44905 | V13: 6 | X13: 9 | Y13: =COUNTIF($U$4:$V$274,X13) -> 15 | Z13: =Y13/$Y$15 -> 0.055350554
A14: 44918 | B14: 27.770156 | D14: 44926 | E14: 20 | G14: 44934 | H14: 9 | L14: 44906 | M14: 0.05 | U14: 44906 | V14: 0 | X14: 10 | Y14: =COUNTIF($U$4:$V$274,X14) -> 13 | Z14: =Y14/$Y$15 -> 0.04797048
A15: 44922 | B15: 21.885614 | D15: 44935 | E15: 21 | G15: 44939 | H15: 7 | L15: 44907 | M15: 0.25 | U15: 44907 | V15: 10 | Y15: =SUM(Y4:Y14) -> 271 | Z15: =SUM(Z4:Z14) -> 1 | AA15: Total
A16: 44925 | B16: 21.281992 | D16: 44937 | E16: 16 | G16: 44946 | H16: 10 | L16: 44908 | M16: 0.2 | U16: 44908 | V16: 8
A17: 44927 | B17: 27.679355 | D17: 44941 | E17: 11 | G17: 44947 | H17: 6 | L17: 44909 | M17: 0.05 | U17: 44909 | V17: 2
A18: 44928 | B18: 24.177148 | D18: 44943 | E18: 14 | G18: 44948 | H18: 7 | L18: 44910 | M18: 0.05 | U18: 44910 | V18: 1
A19: 44932 | B19: 24.357936 | D19: 44944 | E19: 13 | G19: 44949 | H19: 7 | L19: 44911 | M19: 0.05 | U19: 44911 | V19: 1
A20: 44933 | B20: 23.995645 | D20: 44950 | E20: 21 | G20: 44951 | H20: 5 | L20: 44912 | M20: 0.1 | U20: 44912 | V20: 3
A21: 44936 | B21: 24.719042 | D21: 44956 | E21: 15 | G21: 44958 | H21: 7 | L21: 44913 | M21: 0.15 | U21: 44913 | V21: 3
A22: 44938 | B22: 18.39778 | D22: 44959 | E22: 17 | G22: 44963 | H22: 9 | L22: 44914 | M22: 0.1 | U22: 44914 | V22: 3
A23: 44940 | B23: 24.268159 | D23: 44961 | E23: 18 | G23: 44965 | H23: 6 | L23: 44915 | M23: 0.1 | U23: 44915 | V23: 2
A24: 44942 | B24: 23.400737 | D24: 44974 | E24: 17 | G24: 44966 | H24: 8 | L24: 44916 | M24: 0.15 | U24: 44916 | V24: 4
A25: 44945 | B25: 24.240217 | D25: 44977 | E25: 15 | G25: 44969 | H25: 11 | L25: 44917 | M25: 0.05 | U25: 44917 | V25: 1
A26: 44952 | B26: 19.565117 | D26: 44978 | E26: 16 | G26: 44970 | H26: 6 | L26: 44918 | M26: 0.1 | U26: 44918 | V26: 2
A27: 44953 | B27: 24.933792 | D27: 44983 | E27: 16 | G27: 44971 | H27: 9 | L27: 44919 | M27: 0.1 | U27: 44919 | V27: 3
... A85: 45654 | B85: 21.873239 | D85: 45714 | E85: 21 | G85: 45702 | H85: 8 | L85: 44977 | M85: 0.15 | U85: 44977 | V85: 4
A86: 45655 | B86: 23.68445 | G86: 45703 | H86: 6 | L86: 44978 | M86: 0.1 | U86: 44978 | V86: 3
A87: 45659 | B87: 21.224431 | G87: 45707 | H87: 4 | L87: 44979 | M87: 0.05 | U87: 44979 | V87: 1
A88: 45661 | B88: 22.375614 | G88: 45710 | H88: 8 | L88: 44980 | M88: 0.1 | U88: 44980 | V88: 3
A89: 45662 | B89: 19.548988 | G89: 45711 | H89: 8 | L89: 44981 | M89: 0.1 | U89: 44981 | V89: 3
A90: 45668 | B90: 17.979875 | G90: 45712 | H90: 6 | L90: 44982 | M90: 0.15 | U90: 44982 | V90: 6
A91: 45670 | B91: 19.986951 | G91: 45713 | H91: 6 | L91: 44983 | M91: 0.15 | U91: 44983 | V91: 4
A92: 45671 | B92: 17.367662 | G92: 45716 | H92: 5 | L92: 44984 | M92: 0.2 | U92: 44984 | V92: 8
A93: 45680 | B93: 24.411205 | L93: 44985 | M93: 0.15 | U93: 44985 | V93: 3
A94: 45682 | B94: 17.542631 | L94: 45261 | M94: 0.05 | U94: 45261 | V94: 1
A95: 45683 | B95: 20.992517 | L95: 45262 | M95: 0.15 | U95: 45262 | V95: 6
A96: 45685 | B96: 26.138578 | L96: 45263 | M96: 0.2 | U96: 45263 | V96: 7
A97: 45690 | B97: 20.129942 | L97: 45264 | M97: 0.15 | U97: 45264 | V97: 3
...

Sheet 3.b Probability Distributions
A1: S Input 1 - Daily Online Reservation | H1: S Input 2 - Late Cancellation Percentage | S1: S Input 3 - Walk-in Arrivals | AC1: S Input 4 - Miscellaneous Daily Expenses
F3: =IF(#REF!>(#REF!-#REF!)/(#REF!-#REF!),#REF!-SQRT((1-#REF!)*(#REF!-#REF!)*(#REF!-#REF!)),#REF!+SQRT(#REF!*(#REF!-#REF!)*(#REF!-#REF!))) -> #REF!
F4: =IF(#REF!>(#REF!-#REF!)/(#REF!-#REF!),#REF!-SQRT((1-#REF!)*(#REF!-#REF!)*(#REF!-#REF!)),#REF!+SQRT(#REF!*(#REF!-#REF!)*(#REF!-#REF!))) -> #REF! | J4: Late Cancellation Portions | K4: Probability | L4: Cumulative distribution | N4: Lower limit | O4: Upper limit | P4: ='1.a Manager''s Page'!B5 -> Late cancellations percentage | T4: No. of Arrivals | U4: Probability | V4: Cumulative | X4: Lower limit | Y4: Upper limit | Z4: No. of arrivals | AG4: Lower limit | AH4: Upper limit
F5: =IF(#REF!>(#REF!-#REF!)/(#REF!-#REF!),#REF!-SQRT((1-#REF!)*(#REF!-#REF!)*(#REF!-#REF!)),#REF!+SQRT(#REF!*(#REF!-#REF!)*(#REF!-#REF!))) -> #REF! | V5: distribution | X5: Lower limit | Y5: Upper Limit
F6: =IF(#REF!>(#REF!-#REF!)/(#REF!-#REF!),#REF!-SQRT((1-#REF!)*(#REF!-#REF!)*(#REF!-#REF!)),#REF!+SQRT(#REF!*(#REF!-#REF!)*(#REF!-#REF!))) -> #REF! | J6: 0.05 | K6: ='3.a Observed Data'!Q4 -> 0.26937269 | L6: =K6 -> 0.26937269 | N6: 0 | O6: =L6 -> 0.26937269 | P6: =J6 -> 0.05 | T6: 0 | U6: ='3.a Observed Data'!Z4 -> 0.055350554 | V6: =U6 -> 0.055350554 | X6: 0 | Y6: =V6 -> 0.055350554 | Z6: 0 | AF6: Uniform | AG6: 100 | AH6: 600
F7: =IF(#REF!>(#REF!-#REF!)/(#REF!-#REF!),#REF!-SQRT((1-#REF!)*(#REF!-#REF!)*(#REF!-#REF!)),#REF!+SQRT(#REF!*(#REF!-#REF!)*(#REF!-#REF!))) -> #REF! | J7: 0.1 | K7: ='3.a Observed Data'!Q5 -> 0.19188192 | L7: =L6+K7 -> 0.46125461 | N7: =O6 -> 0.26937269 | O7: =L7 -> 0.46125461 | P7: =J7 -> 0.1 | T7: 1 | U7: ='3.a Observed Data'!Z5 -> 0.16605166 | V7: =V6+U7 -> 0.22140221 | X7: =Y6 -> 0.055350554 | Y7: =V7 -> 0.22140221 | Z7: 1
F8: =IF(#REF!>(#REF!-#REF!)/(#REF!-#REF!),#REF!-SQRT((1-#REF!)*(#REF!-#REF!)*(#REF!-#REF!)),#REF!+SQRT(#REF!*(#REF!-#REF!)*(#REF!-#REF!))) -> #REF! | J8: 0.15 | K8: ='3.a Observed Data'!Q6 -> 0.28782288 | L8: =L7+K8 -> 0.74907749 | N8: =O7 -> 0.46125461 | O8: =L8 -> 0.74907749 | P8: =J8 -> 0.15 | T8: 2 | U8: ='3.a Observed Data'!Z6 -> 0.099630996 | V8: =V7+U8 -> 0.32103321 | X8: =Y7 -> 0.22140221 | Y8: =V8 -> 0.32103321 | Z8: 2
F9: =IF(#REF!>(#REF!-#REF!)/(#REF!-#REF!),#REF!-SQRT((1-#REF!)*(#REF!-#REF!)*(#REF!-#REF!)),#REF!+SQRT(#REF!*(#REF!-#REF!)*(#REF!-#REF!))) -> #REF! | J9: 0.2 | K9: ='3.a Observed Data'!Q7 -> 0.14760148 | L9: =L8+K9 -> 0.89667897 | N9: =O8 -> 0.74907749 | O9: =L9 -> 0.89667897 | P9: =J9 -> 0.2 | T9: 3 | U9: ='3.a Observed Data'!Z7 -> 0.26568266 | V9: =V8+U9 -> 0.58671587 | X9: =Y8 -> 0.32103321 | Y9: =V9 -> 0.58671587 | Z9: 3 | AD9: Miscellaneous Daily Expenses | AG9: =RAND() -> 0.70745741 | AH9: =$AG$6+($AH$6-$AG$6)*$AG$9 -> 453.7287
C10: Mean | D10: Standard deviation | F10: =IF(#REF!>(#REF!-#REF!)/(#REF!-#REF!),#REF!-SQRT((1-#REF!)*(#REF!-#REF!)*(#REF!-#REF!)),#REF!+SQRT(#REF!*(#REF!-#REF!)*(#REF!-#REF!))) -> #REF! | J10: 0.25 | K10: ='3.a Observed Data'!Q8 -> 0.10332103 | L10: =L9+K10 -> 1 | N10: =O9 -> 0.89667897 | O10: =L10 -> 1 | P10: =J10 -> 0.25 | T10: 4 | U10: ='3.a Observed Data'!Z8 -> 0.088560886 | V10: =V9+U10 -> 0.67527675 | X10: =Y9 -> 0.58671587 | Y10: =V10 -> 0.67527675 | Z10: 4
B11: Price at $120 | C11: =AVERAGE('3.a Observed Data'!B4:B103) -> 22.269787 | D11: =C11*0.17 -> 3.7858638 | F11: =IF(#REF!>(#REF!-#REF!)/(#REF!-#REF!),#REF!-SQRT((1-#REF!)*(#REF!-#REF!)*(#REF!-#REF!)),#REF!+SQRT(#REF!*(#REF!-#REF!)*(#REF!-#REF!))) -> #REF! | T11: 5 | U11: ='3.a Observed Data'!Z9 -> 0.022140221 | V11: =V10+U11 -> 0.69741697 | X11: =Y10 -> 0.67527675 | Y11: =V11 -> 0.69741697 | Z11: 5
B12: Price at $150 | C12: =AVERAGE('3.a Observed Data'!E4:E85) -> 17.97561 | D12: =C12*0.17 -> 3.0558537 | F12: =IF(#REF!>(#REF!-#REF!)/(#REF!-#REF!),#REF!-SQRT((1-#REF!)*(#REF!-#REF!)*(#REF!-#REF!)),#REF!+SQRT(#REF!*(#REF!-#REF!)*(#REF!-#REF!))) -> #REF! | T12: 6 | U12: ='3.a Observed Data'!Z10 -> 0.051660517 | V12: =V11+U12 -> 0.74907749 | X12: =Y11 -> 0.69741697 | Y12: =V12 -> 0.74907749 | Z12: 6
B13: Price at $180 | C13: =AVERAGE('3.a Observed Data'!H4:H92) -> 6.9662921 | D13: =C13*0.17 -> 1.1842697 | F13: =IF(#REF!>(#REF!-#REF!)/(#REF!-#REF!),#REF!-SQRT((1-#REF!)*(#REF!-#REF!)*(#REF!-#REF!)),#REF!+SQRT(#REF!*(#REF!-#REF!)*(#REF!-#REF!))) -> #REF! | T13: 7 | U13: ='3.a Observed Data'!Z11 -> 0.036900369 | V13: =V12+U13 -> 0.78597786 | X13: =Y12 -> 0.74907749 | Y13: =V13 -> 0.78597786 | Z13: 7
F14: =IF(#REF!>(#REF!-#REF!)/(#REF!-#REF!),#REF!-SQRT((1-#REF!)*(#REF!-#REF!)*(#REF!-#REF!)),#REF!+SQRT(#REF!*(#REF!-#REF!)*(#REF!-#REF!))) -> #REF! | T14: 8 | U14: ='3.a Observed Data'!Z12 -> 0.11070111 | V14: =V13+U14 -> 0.89667897 | X14: =Y13 -> 0.78597786 | Y14: =V14 -> 0.89667897 | Z14: 8
B15: Daily online reservation when price $120 | C15: =RAND() -> 0.83057782 | D15: =MAX(0,_xlfn.NORM.INV($C$15,$C$11,$D$11)) -> 25.890781 | F15: =IF(#REF!>(#REF!-#REF!)/(#REF!-#REF!),#REF!-SQRT((1-#REF!)*(#REF!-#REF!)*(#REF!-#REF!)),#REF!+SQRT(#REF!*(#REF!-#REF!)*(#REF!-#REF!))) -> #REF! | T15: 9 | U15: ='3.a Observed Data'!Z13 -> 0.055350554 | V15: =V14+U15 -> 0.95202952 | X15: =Y14 -> 0.89667897 | Y15: =V15 -> 0.95202952 | Z15: 9
B16: Daily online reservation when price $150 | C16: =RAND() -> 0.46332073 | D16: =MAX(0,_xlfn.NORM.INV($C$16,$C$12,$D$12)) -> 17.694254 | F16: =IF(#REF!>(#REF!-#REF!)/(#REF!-#REF!),#REF!-SQRT((1-#REF!)*(#REF!-#REF!)*(#REF!-#REF!)),#REF!+SQRT(#REF!*(#REF!-#REF!)*(#REF!-#REF!))) -> #REF! | T16: 10 | U16: ='3.a Observed Data'!Z14 -> 0.04797048 | V16: =V15+U16 -> 1 | X16: =Y15 -> 0.95202952 | Y16: =V16 -> 1 | Z16: 10
B17: Daily online reservation when price $180 | C17: =RAND() -> 0.16817027 | D17: =MAX(0,_xlfn.NORM.INV($C$17,$C$13,$D$13)) -> 5.8277105 | F17: =IF(#REF!>(#REF!-#REF!)/(#REF!-#REF!),#REF!-SQRT((1-#REF!)*(#REF!-#REF!)*(#REF!-#REF!)),#REF!+SQRT(#REF!*(#REF!-#REF!)*(#REF!-#REF!))) -> #REF!
F18: =IF(#REF!>(#REF!-#REF!)/(#REF!-#REF!),#REF!-SQRT((1-#REF!)*(#REF!-#REF!)*(#REF!-#REF!)),#REF!+SQRT(#REF!*(#REF!-#REF!)*(#REF!-#REF!))) -> #REF!
F19: =IF(#REF!>(#REF!-#REF!)/(#REF!-#REF!),#REF!-SQRT((1-#REF!)*(#REF!-#REF!)*(#REF!-#REF!)),#REF!+SQRT(#REF!*(#REF!-#REF!)*(#REF!-#REF!))) -> #REF!
F20: =IF(#REF!>(#REF!-#REF!)/(#REF!-#REF!),#REF!-SQRT((1-#REF!)*(#REF!-#REF!)*(#REF!-#REF!)),#REF!+SQRT(#REF!*(#REF!-#REF!)*(#REF!-#REF!))) -> #REF!
F21: =IF(#REF!>(#REF!-#REF!)/(#REF!-#REF!),#REF!-SQRT((1-#REF!)*(#REF!-#REF!)*(#REF!-#REF!)),#REF!+SQRT(#REF!*(#REF!-#REF!)*(#REF!-#REF!))) -> #REF!
F22: =IF(#REF!>(#REF!-#REF!)/(#REF!-#REF!),#REF!-SQRT((1-#REF!)*(#REF!-#REF!)*(#REF!-#REF!)),#REF!+SQRT(#REF!*(#REF!-#REF!)*(#REF!-#REF!))) -> #REF!
F23: =IF(#REF!>(#REF!-#REF!)/(#REF!-#REF!),#REF!-SQRT((1-#REF!)*(#REF!-#REF!)*(#REF!-#REF!)),#REF!+SQRT(#REF!*(#REF!-#REF!)*(#REF!-#REF!))) -> #REF!
F24: =IF(#REF!>(#REF!-#REF!)/(#REF!-#REF!),#REF!-SQRT((1-#REF!)*(#REF!-#REF!)*(#REF!-#REF!)),#REF!+SQRT(#REF!*(#REF!-#REF!)*(#REF!-#REF!))) -> #REF!
F25: =IF(#REF!>(#REF!-#REF!)/(#REF!-#REF!),#REF!-SQRT((1-#REF!)*(#REF!-#REF!)*(#REF!-#REF!)),#REF!+SQRT(#REF!*(#REF!-#REF!)*(#REF!-#REF!))) -> #REF!
F26: =IF(#REF!>(#REF!-#REF!)/(#REF!-#REF!),#REF!-SQRT((1-#REF!)*(#REF!-#REF!)*(#REF!-#REF!)),#REF!+SQRT(#REF!*(#REF!-#REF!)*(#REF!-#REF!))) -> #REF!
F27: =IF(#REF!>(#REF!-#REF!)/(#REF!-#REF!),#REF!-SQRT((1-#REF!)*(#REF!-#REF!)*(#REF!-#REF!)),#REF!+SQRT(#REF!*(#REF!-#REF!)*(#REF!-#REF!))) -> #REF!
F28: =IF(#REF!>(#REF!-#REF!)/(#REF!-#REF!),#REF!-SQRT((1-#REF!)*(#REF!-#REF!)*(#REF!-#REF!)),#REF!+SQRT(#REF!*(#REF!-#REF!)*(#REF!-#REF!))) -> #REF!
F29: =IF(#REF!>(#REF!-#REF!)/(#REF!-#REF!),#REF!-SQRT((1-#REF!)*(#REF!-#REF!)*(#REF!-#REF!)),#REF!+SQRT(#REF!*(#REF!-#REF!)*(#REF!-#REF!))) -> #REF!
... F275: =IF(#REF!>(#REF!-#REF!)/(#REF!-#REF!),#REF!-SQRT((1-#REF!)*(#REF!-#REF!)*(#REF!-#REF!)),#REF!+SQRT(#REF!*(#REF!-#REF!)*(#REF!-#REF!))) -> #REF!

Sheet 4.a Simulation
B2: SIMULATION OF 1000 TRIALS AT PRICE $120 WITH OVER BOOKING LEVEL AT 10% AND LATE CANCELLATION FEE AT 10% | T2: TRACKING CONVERGENCE OF OUTPUT MEANS | AF2: CONVERGENCE OF MEAN CHART FOR CALCULATED OUTPUTS AND TOTAL DAILY PROFIT | BA2: SIMULATION OF 1000 TRIALS AT PRICE $150 OVER BOOKING LEVEL AT 10% AND LATE CANCELLATION FEE AT 10% | BR2: TRACKING CONVERGENCE OF OUTPUT MEANS | CE2: CONVERGENCE OF MEAN CHART FOR CALCULATED OUTPUTS AND TOTAL DAILY PROFIT | DF2: SIMULATION OF 1000 TRIALS AT PRICE $180 OVER BOOKING LEVEL AT 10% AND LATE CANCELLATION FEE AT 10% | DX2: TRACKING CONVERGENCE OF OUTPUT MEANS | EJ2: CONVERGENCE OF MEAN CHART FOR CALCULATED OUTPUTS AND TOTAL DAILY PROFIT | FJ2: SIMULATION OF 1000 TRIALS AT PRICE $180 WITH OVER BOOKING LEVEL AT 15% AND LATE CANCELLATION FEE AT 20% | GB2: TRACKING CONVERGENCE OF OUTPUT MEANS | GN2: CONVERGENCE OF MEAN CHART FOR CALCULATED OUTPUTS AND TOTAL DAILY PROFIT | HM2: SIMULATION OF 1000 TRIALS AT PRICE $150 WITH OVER BOOKING LEVEL AT 15% AND LATE CANCELLATION FEE AT 20% | IE2: TRACKING CONVERGENCE OF OUTPUT MEANS | IQ2: CONVERGENCE OF MEAN CHART FOR CALCULATED OUTPUTS AND TOTAL DAILY PROFIT
B4: Simulation trials | C4: ='1.a Manager''s Page'!B4 -> Daily online reservations | D4: ='1.a Manager''s Page'!B5 -> Late cancellations percentage | E4: ='1.a Manager''s Page'!B6 -> Walk-in arrivals | F4: ='1.a Manager''s Page'!B7 -> Miscellaneuous daily expenses | G4: ='1.a Manager''s Page'!B22 -> Net demand | H4: ='1.a Manager''s Page'!B23 -> Room sold | I4: ='1.a Manager''s Page'!B24 -> Bumped guests | J4: ='1.a Manager''s Page'!B25 -> Revenue from stays | K4: ='1.a Manager''s Page'!B26 -> Total compensation cost | L4: ='1.a Manager''s Page'!B27 -> Total housekeeping cost | M4: ='1.a Manager''s Page'!B28 -> Total utilities cost | N4: ='1.a Manager''s Page'!B29 -> Total fixed inputs cost | O4: ='1.a Manager''s Page'!B30 -> Late no shows | P4: ='1.a Manager''s Page'!B31 -> Late cancellation fee revenue | Q4: ='1.a Manager''s Page'!B34 -> Total Daily Profit | R4: ='1.a Manager''s Page'!B35 -> Sold Out: Yes/ No | T4: =G4 -> Net demand | U4: =H4 -> Room sold | V4: =I4 -> Bumped guests | W4: =J4 -> Revenue from stays | X4: =K4 -> Total compensation cost | Y4: =L4 -> Total housekeeping cost | Z4: =M4 -> Total utilities cost | AA4: =N4 -> Total fixed inputs cost | ... AD4: =Q4 -> Total Daily Profit | AZ4: =B4 -> Simulation trials | BA4: =C4 -> Daily online reservations | BB4: =D4 -> Late cancellations percentage | BC4: =E4 -> Walk-in arrivals | BD4: =F4 -> Miscellaneuous daily expenses | BE4: =G4 -> Net demand | BF4: =H4 -> Room sold | BG4: =I4 -> Bumped guests | ... BP4: =R4 -> Sold Out: Yes/ No | BR4: =BE4 -> Net demand | BS4: =BF4 -> Room sold | BT4: =BG4 -> Bumped guests | BU4: =BH4 -> Revenue from stays | BV4: =BI4 -> Total compensation cost | BW4: =BJ4 -> Total housekeeping cost | BX4: =BK4 -> Total utilities cost | BY4: =BL4 -> Total fixed inputs cost | ... CB4: =BO4 -> Total Daily Profit | DF4: =AZ4 -> Simulation trials | DG4: =BA4 -> Daily online reservations | DH4: =BB4 -> Late cancellations percentage | DI4: =BC4 -> Walk-in arrivals | DJ4: =BD4 -> Miscellaneuous daily expenses | DK4: =BE4 -> Net demand | DL4: =BF4 -> Room sold | DM4: =BG4 -> Bumped guests | ... DV4: =BP4 -> Sold Out: Yes/ No | DX4: =DK4 -> Net demand | DY4: =DL4 -> Room sold | DZ4: =DM4 -> Bumped guests | EA4: =DN4 -> Revenue from stays | EB4: =DO4 -> Total compensation cost | EC4: =DP4 -> Total housekeeping cost | ED4: =DQ4 -> Total utilities cost | EE4: =DR4 -> Total fixed inputs cost | ... EH4: =DU4 -> Total Daily Profit | FJ4: =B4 -> Simulation trials | FK4: =C4 -> Daily online reservations | FL4: =D4 -> Late cancellations percentage | FM4: =E4 -> Walk-in arrivals | FN4: =F4 -> Miscellaneuous daily expenses | FO4: =G4 -> Net demand | FP4: =H4 -> Room sold | FQ4: =I4 -> Bumped guests | ... FZ4: =R4 -> Sold Out: Yes/ No | GB4: =BR4 -> Net demand | GC4: =BS4 -> Room sold | GD4: =BT4 -> Bumped guests | GE4: =BU4 -> Revenue from stays | GF4: =BV4 -> Total compensation cost | GG4: =BW4 -> Total housekeeping cost | GH4: =BX4 -> Total utilities cost | GI4: =BY4 -> Total fixed inputs cost | ... GL4: =CB4 -> Total Daily Profit | HM4: =B4 -> Simulation trials | HN4: =C4 -> Daily online reservations | HO4: =D4 -> Late cancellations percentage | HP4: =E4 -> Walk-in arrivals | HQ4: =F4 -> Miscellaneuous daily expenses | HR4: =G4 -> Net demand | HS4: =H4 -> Room sold | HT4: =I4 -> Bumped guests | ... IC4: =R4 -> Sold Out: Yes/ No | IE4: =GB4 -> Net demand | IF4: =GC4 -> Room sold | IG4: =GD4 -> Bumped guests | IH4: =GE4 -> Revenue from stays | II4: =GF4 -> Total compensation cost | IJ4: =GG4 -> Total housekeeping cost | IK4: =GH4 -> Total utilities cost | IL4: =GI4 -> Total fixed inputs cost | ... IO4: =GL4 -> Total Daily Profit
C5: ='1.c Model Simulated data'!H4 -> 5.8277105 | D5: ='1.c Model Simulated data'!H5 -> 0.25 | E5: ='1.c Model Simulated data'!H6 -> 8 | F5: ='1.c Model Simulated data'!H7 -> 454 | G5: ='1.c Model Simulated data'!C4 -> 13 | H5: ='1.c Model Simulated data'!C5 -> 13 | I5: ='1.c Model Simulated data'!C6 -> 0 | J5: ='1.c Model Simulated data'!C7 -> 2340 | K5: ='1.c Model Simulated data'!C8 -> 0 | L5: ='1.c Model Simulated data'!C9 -> 650 | M5: ='1.c Model Simulated data'!C10 -> 195 | N5: ='1.c Model Simulated data'!C12 -> 1924 | O5: ='1.c Model Simulated data'!C13 -> 1 | P5: ='1.c Model Simulated data'!C14 -> 18 | Q5: ='1.c Model Simulated data'!C17 -> 434 | R5: ='1.c Model Simulated data'!C18 -> No | BA5: ='1.c Model Simulated data'!H4 -> 5.8277105 | BB5: ='1.c Model Simulated data'!H5 -> 0.25 | BC5: ='1.c Model Simulated data'!H6 -> 8 | BD5: ='1.c Model Simulated data'!H7 -> 454 | BE5: ='1.c Model Simulated data'!C4 -> 13 | BF5: ='1.c Model Simulated data'!C5 -> 13 | BG5: ='1.c Model Simulated data'!C6 -> 0 | BH5: ='1.c Model Simulated data'!C7 -> 2340 | BI5: ='1.c Model Simulated data'!C8 -> 0 | BJ5: ='1.c Model Simulated data'!C9 -> 650 | BK5: ='1.c Model Simulated data'!C10 -> 195 | BL5: ='1.c Model Simulated data'!C12 -> 1924 | BM5: ='1.c Model Simulated data'!C13 -> 1 | BN5: ='1.c Model Simulated data'!C14 -> 18 | BO5: ='1.c Model Simulated data'!C17 -> 434 | BP5: ='1.c Model Simulated data'!C18 -> No | DG5: ='1.c Model Simulated data'!H4 -> 5.8277105 | DH5: ='1.c Model Simulated data'!H5 -> 0.25 | DI5: ='1.c Model Simulated data'!H6 -> 8 | DJ5: ='1.c Model Simulated data'!H7 -> 454 | DK5: ='1.c Model Simulated data'!C4 -> 13 | DL5: ='1.c Model Simulated data'!C5 -> 13 | DM5: ='1.c Model Simulated data'!C6 -> 0 | DN5: ='1.c Model Simulated data'!C7 -> 2340 | DO5: ='1.c Model Simulated data'!C8 -> 0 | DP5: ='1.c Model Simulated data'!C9 -> 650 | DQ5: ='1.c Model Simulated data'!C10 -> 195 | DR5: ='1.c Model Simulated data'!C12 -> 1924 | DS5: ='1.c Model Simulated data'!C13 -> 1 | DT5: ='1.c Model Simulated data'!C14 -> 18 | DU5: ='1.c Model Simulated data'!C17 -> 434 | DV5: ='1.c Model Simulated data'!C18 -> No | FK5: ='1.c Model Simulated data'!H4 -> 5.8277105 | FL5: ='1.c Model Simulated data'!H5 -> 0.25 | FM5: ='1.c Model Simulated data'!H6 -> 8 | FN5: ='1.c Model Simulated data'!H7 -> 454 | FO5: ='1.c Model Simulated data'!C4 -> 13 | FP5: ='1.c Model Simulated data'!C5 -> 13 | FQ5: ='1.c Model Simulated data'!C6 -> 0 | FR5: ='1.c Model Simulated data'!C7 -> 2340 | FS5: ='1.c Model Simulated data'!C8 -> 0 | FT5: ='1.c Model Simulated data'!C9 -> 650 | FU5: ='1.c Model Simulated data'!C10 -> 195 | FV5: ='1.c Model Simulated data'!C12 -> 1924 | FW5: ='1.c Model Simulated data'!C13 -> 1 | FX5: ='1.c Model Simulated data'!C14 -> 18 | FY5: ='1.c Model Simulated data'!C17 -> 434 | FZ5: ='1.c Model Simulated data'!C18 -> No | HN5: ='1.c Model Simulated data'!H4 -> 5.8277105 | HO5: ='1.c Model Simulated data'!H5 -> 0.25 | HP5: ='1.c Model Simulated data'!H6 -> 8 | HQ5: ='1.c Model Simulated data'!H7 -> 454 | HR5: ='1.c Model Simulated data'!C4 -> 13 | HS5: ='1.c Model Simulated data'!C5 -> 13 | HT5: ='1.c Model Simulated data'!C6 -> 0 | HU5: ='1.c Model Simulated data'!C7 -> 2340 | HV5: ='1.c Model Simulated data'!C8 -> 0 | HW5: ='1.c Model Simulated data'!C9 -> 650 | HX5: ='1.c Model Simulated data'!C10 -> 195 | HY5: ='1.c Model Simulated data'!C12 -> 1924 | HZ5: ='1.c Model Simulated data'!C13 -> 1 | IA5: ='1.c Model Simulated data'!C14 -> 18 | IB5: ='1.c Model Simulated data'!C17 -> 434 | IC5: ='1.c Model Simulated data'!C18 -> No
